Goin' Fast @ http://127.0.0.1:8075
Sanic tried to use loop.add_signal_handler but it is not implemented on this platform.
Sanic tried to use loop.add_signal_handler but it is not implemented on this platform.
Starting worker [39312]

Pika version 1.1.0 connecting to ('::1', 5672, 0, 0)
Socket connected: <socket.socket fd=1876, family=AddressFamily.AF_INET6, type=SocketKind.SOCK_STREAM, proto=6, laddr=('::1', 64986, 0, 0), raddr=('::1', 5672, 0, 0)>
Streaming transport linked up: (<pika.adapters.utils.io_services_utils._AsyncPlaintextTransport object at 0x0000021B6D01C828>, _StreamingProtocolShim: <SelectConnection PROTOCOL transport=<pika.adapters.utils.io_services_utils._AsyncPlaintextTransport object at 0x0000021B6D01C828> params=<ConnectionParameters host=localhost port=5672 virtual_host=testhost ssl=False>>).
AMQPConnector - reporting success: <SelectConnection OPEN transport=<pika.adapters.utils.io_services_utils._AsyncPlaintextTransport object at 0x0000021B6D01C828> params=<ConnectionParameters host=localhost port=5672 virtual_host=testhost ssl=False>>
AMQPConnectionWorkflow - reporting success: <SelectConnection OPEN transport=<pika.adapters.utils.io_services_utils._AsyncPlaintextTransport object at 0x0000021B6D01C828> params=<ConnectionParameters host=localhost port=5672 virtual_host=testhost ssl=False>>
Connection workflow succeeded: <SelectConnection OPEN transport=<pika.adapters.utils.io_services_utils._AsyncPlaintextTransport object at 0x0000021B6D01C828> params=<ConnectionParameters host=localhost port=5672 virtual_host=testhost ssl=False>>
Created channel=1
Goin' Fast @ http://127.0.0.1:8075
Sanic tried to use loop.add_signal_handler but it is not implemented on this platform.
Sanic tried to use loop.add_signal_handler but it is not implemented on this platform.
Starting worker [19164]
Pika version 1.1.0 connecting to ('::1', 5672, 0, 0)
Socket connected: <socket.socket fd=1996, family=AddressFamily.AF_INET6, type=SocketKind.SOCK_STREAM, proto=6, laddr=('::1', 62359, 0, 0), raddr=('::1', 5672, 0, 0)>
Streaming transport linked up: (<pika.adapters.utils.io_services_utils._AsyncPlaintextTransport object at 0x0000018C22E13860>, _StreamingProtocolShim: <SelectConnection PROTOCOL transport=<pika.adapters.utils.io_services_utils._AsyncPlaintextTransport object at 0x0000018C22E13860> params=<ConnectionParameters host=localhost port=5672 virtual_host=testhost ssl=False>>).
AMQPConnector - reporting success: <SelectConnection OPEN transport=<pika.adapters.utils.io_services_utils._AsyncPlaintextTransport object at 0x0000018C22E13860> params=<ConnectionParameters host=localhost port=5672 virtual_host=testhost ssl=False>>
AMQPConnectionWorkflow - reporting success: <SelectConnection OPEN transport=<pika.adapters.utils.io_services_utils._AsyncPlaintextTransport object at 0x0000018C22E13860> params=<ConnectionParameters host=localhost port=5672 virtual_host=testhost ssl=False>>
Connection workflow succeeded: <SelectConnection OPEN transport=<pika.adapters.utils.io_services_utils._AsyncPlaintextTransport object at 0x0000018C22E13860> params=<ConnectionParameters host=localhost port=5672 virtual_host=testhost ssl=False>>
Created channel=1
Exception occurred while handling uri: 'http://127.0.0.1:8075/python/bpDsStaticInfo'
Traceback (most recent call last):
  File "G:\Project\UTILS\myutils\linksqlUtils.py", line 49, in link_mysql_ifnotexit_creat
    con = link_mysql(database=database) # 会抛出 nameerror 和 pysqllinkexception两种异常
  File "G:\Project\UTILS\myutils\linksqlUtils.py", line 36, in link_mysql
    raise e
  File "G:\Project\UTILS\myutils\linksqlUtils.py", line 32, in link_mysql
    use_unicode=True) # , charset='latin1'
  File "D:\Program Files\Anaconda2\envs\python35\lib\site-packages\pymysql\__init__.py", line 94, in Connect
    return Connection(*args, **kwargs)
  File "D:\Program Files\Anaconda2\envs\python35\lib\site-packages\pymysql\connections.py", line 327, in __init__
    self.connect()
  File "D:\Program Files\Anaconda2\envs\python35\lib\site-packages\pymysql\connections.py", line 598, in connect
    self._request_authentication()
  File "D:\Program Files\Anaconda2\envs\python35\lib\site-packages\pymysql\connections.py", line 862, in _request_authentication
    auth_packet = self._process_auth(plugin_name, auth_packet)
  File "D:\Program Files\Anaconda2\envs\python35\lib\site-packages\pymysql\connections.py", line 933, in _process_auth
    pkt = self._read_packet()
  File "D:\Program Files\Anaconda2\envs\python35\lib\site-packages\pymysql\connections.py", line 683, in _read_packet
    packet.check_error()
  File "D:\Program Files\Anaconda2\envs\python35\lib\site-packages\pymysql\protocol.py", line 220, in check_error
    err.raise_mysql_exception(self._data)
  File "D:\Program Files\Anaconda2\envs\python35\lib\site-packages\pymysql\err.py", line 109, in raise_mysql_exception
    raise errorclass(errno, errval)
pymysql.err.InternalError: (1049, "Unknown database '20191118152056'")

During handling of the above exception, another exception occurred:

Traceback (most recent call last):
  File "D:\Program Files\Anaconda2\envs\python35\lib\site-packages\sanic\app.py", line 915, in handle_request
    response = handler(request, *args, **kwargs)
  File "G:\Project\Trainer\trainer\backend\app\datasetinfo\static\view.py", line 76, in request_dataset_static_info
    dsStaticInfoDict = interface_dataset_static_info(trainName,isGetAll)
  File "G:\Project\Trainer\trainer\backend\app\datasetinfo\static\model.py", line 28, in interface_dataset_static_info
    tdsStaticInfoDict = interface_traindataset_static_info(trainName,isGetAll)
  File "G:\Project\Trainer\trainer\backend\app\datasetinfo\static\model.py", line 11, in interface_traindataset_static_info
    tdsStaticInfoDict = mq_to_sql(topic,tablename,trainName,isGetAll)
  File "G:\Project\Trainer\trainer\backend\app\basemodel.py", line 29, in mq_to_sql
    con = link_mysql_ifnotexit_creat(trainName)
  File "G:\Project\UTILS\myutils\linksqlUtils.py", line 56, in link_mysql_ifnotexit_creat
    curBase.execute(query=querySql)
  File "D:\Program Files\Anaconda2\envs\python35\lib\site-packages\pymysql\cursors.py", line 170, in execute
    result = self._query(query)
  File "D:\Program Files\Anaconda2\envs\python35\lib\site-packages\pymysql\cursors.py", line 328, in _query
    conn.query(q)
  File "D:\Program Files\Anaconda2\envs\python35\lib\site-packages\pymysql\connections.py", line 516, in query
    self._affected_rows = self._read_query_result(unbuffered=unbuffered)
  File "D:\Program Files\Anaconda2\envs\python35\lib\site-packages\pymysql\connections.py", line 727, in _read_query_result
    result.read()
  File "D:\Program Files\Anaconda2\envs\python35\lib\site-packages\pymysql\connections.py", line 1066, in read
    first_packet = self.connection._read_packet()
  File "D:\Program Files\Anaconda2\envs\python35\lib\site-packages\pymysql\connections.py", line 683, in _read_packet
    packet.check_error()
  File "D:\Program Files\Anaconda2\envs\python35\lib\site-packages\pymysql\protocol.py", line 220, in check_error
    err.raise_mysql_exception(self._data)
  File "D:\Program Files\Anaconda2\envs\python35\lib\site-packages\pymysql\err.py", line 109, in raise_mysql_exception
    raise errorclass(errno, errval)
pymysql.err.ProgrammingError: (1064, "You have an error in your SQL syntax; check the manual that corresponds to your MySQL server version for the right syntax to use near '20191118152056 Character Set UTF8' at line 1")

Goin' Fast @ http://127.0.0.1:8075
Sanic tried to use loop.add_signal_handler but it is not implemented on this platform.
Sanic tried to use loop.add_signal_handler but it is not implemented on this platform.
Starting worker [25060]
Exception occurred while handling uri: 'http://127.0.0.1:8075/python/bpDsDynamicInfo'
Traceback (most recent call last):
  File "D:\Program Files\Anaconda2\envs\python35\lib\site-packages\sanic\app.py", line 893, in handle_request
    handler, args, kwargs, uri = self.router.get(request)
  File "D:\Program Files\Anaconda2\envs\python35\lib\site-packages\sanic\router.py", line 407, in get
    return self._get(request.path, request.method, "")
  File "D:\Program Files\Anaconda2\envs\python35\lib\site-packages\sanic\router.py", line 469, in _get
    raise NotFound("Requested URL {} not found".format(url))
sanic.exceptions.NotFound: Requested URL /python/bpDsDynamicInfo not found

Goin' Fast @ http://127.0.0.1:8075
Sanic tried to use loop.add_signal_handler but it is not implemented on this platform.
Sanic tried to use loop.add_signal_handler but it is not implemented on this platform.
Starting worker [35452]
Pika version 1.1.0 connecting to ('::1', 5672, 0, 0)
Socket connected: <socket.socket fd=1624, family=AddressFamily.AF_INET6, type=SocketKind.SOCK_STREAM, proto=6, laddr=('::1', 54108, 0, 0), raddr=('::1', 5672, 0, 0)>
Streaming transport linked up: (<pika.adapters.utils.io_services_utils._AsyncPlaintextTransport object at 0x0000022A0D204B00>, _StreamingProtocolShim: <SelectConnection PROTOCOL transport=<pika.adapters.utils.io_services_utils._AsyncPlaintextTransport object at 0x0000022A0D204B00> params=<ConnectionParameters host=localhost port=5672 virtual_host=testhost ssl=False>>).
AMQPConnector - reporting success: <SelectConnection OPEN transport=<pika.adapters.utils.io_services_utils._AsyncPlaintextTransport object at 0x0000022A0D204B00> params=<ConnectionParameters host=localhost port=5672 virtual_host=testhost ssl=False>>
AMQPConnectionWorkflow - reporting success: <SelectConnection OPEN transport=<pika.adapters.utils.io_services_utils._AsyncPlaintextTransport object at 0x0000022A0D204B00> params=<ConnectionParameters host=localhost port=5672 virtual_host=testhost ssl=False>>
Connection workflow succeeded: <SelectConnection OPEN transport=<pika.adapters.utils.io_services_utils._AsyncPlaintextTransport object at 0x0000022A0D204B00> params=<ConnectionParameters host=localhost port=5672 virtual_host=testhost ssl=False>>
Created channel=1
Exception occurred while handling uri: 'http://127.0.0.1:8075/python/bpDsDynamicInfo'
Traceback (most recent call last):
  File "D:\Program Files\Anaconda2\envs\python35\lib\site-packages\sanic\app.py", line 915, in handle_request
    response = handler(request, *args, **kwargs)
  File "G:\Project\Trainer\trainer\backend\app\datasetinfo\dynamic\view.py", line 47, in request_dataset_dynamic_info
    return response.json(body=responseJson)
  File "D:\Program Files\Anaconda2\envs\python35\lib\site-packages\sanic\response.py", line 220, in json
    dumps(body, **kwargs),
OverflowError: Maximum recursion level reached

Pika version 1.1.0 connecting to ('::1', 5672, 0, 0)
Socket connected: <socket.socket fd=1568, family=AddressFamily.AF_INET6, type=SocketKind.SOCK_STREAM, proto=6, laddr=('::1', 58952, 0, 0), raddr=('::1', 5672, 0, 0)>
Streaming transport linked up: (<pika.adapters.utils.io_services_utils._AsyncPlaintextTransport object at 0x0000022A0D3EAA90>, _StreamingProtocolShim: <SelectConnection PROTOCOL transport=<pika.adapters.utils.io_services_utils._AsyncPlaintextTransport object at 0x0000022A0D3EAA90> params=<ConnectionParameters host=localhost port=5672 virtual_host=testhost ssl=False>>).
AMQPConnector - reporting success: <SelectConnection OPEN transport=<pika.adapters.utils.io_services_utils._AsyncPlaintextTransport object at 0x0000022A0D3EAA90> params=<ConnectionParameters host=localhost port=5672 virtual_host=testhost ssl=False>>
AMQPConnectionWorkflow - reporting success: <SelectConnection OPEN transport=<pika.adapters.utils.io_services_utils._AsyncPlaintextTransport object at 0x0000022A0D3EAA90> params=<ConnectionParameters host=localhost port=5672 virtual_host=testhost ssl=False>>
Connection workflow succeeded: <SelectConnection OPEN transport=<pika.adapters.utils.io_services_utils._AsyncPlaintextTransport object at 0x0000022A0D3EAA90> params=<ConnectionParameters host=localhost port=5672 virtual_host=testhost ssl=False>>
Created channel=1
Exception occurred while handling uri: 'http://127.0.0.1:8075/python/bpDsDynamicInfo'
Traceback (most recent call last):
  File "D:\Program Files\Anaconda2\envs\python35\lib\site-packages\sanic\app.py", line 915, in handle_request
    response = handler(request, *args, **kwargs)
  File "G:\Project\Trainer\trainer\backend\app\datasetinfo\dynamic\view.py", line 47, in request_dataset_dynamic_info
    return response.json(body=responseJson)
  File "D:\Program Files\Anaconda2\envs\python35\lib\site-packages\sanic\response.py", line 220, in json
    dumps(body, **kwargs),
OverflowError: Maximum recursion level reached

Goin' Fast @ http://127.0.0.1:8075
Sanic tried to use loop.add_signal_handler but it is not implemented on this platform.
Sanic tried to use loop.add_signal_handler but it is not implemented on this platform.
Starting worker [13652]
Pika version 1.1.0 connecting to ('::1', 5672, 0, 0)
Socket connected: <socket.socket fd=1592, family=AddressFamily.AF_INET6, type=SocketKind.SOCK_STREAM, proto=6, laddr=('::1', 59021, 0, 0), raddr=('::1', 5672, 0, 0)>
Streaming transport linked up: (<pika.adapters.utils.io_services_utils._AsyncPlaintextTransport object at 0x00000258EEEA1B70>, _StreamingProtocolShim: <SelectConnection PROTOCOL transport=<pika.adapters.utils.io_services_utils._AsyncPlaintextTransport object at 0x00000258EEEA1B70> params=<ConnectionParameters host=localhost port=5672 virtual_host=testhost ssl=False>>).
AMQPConnector - reporting success: <SelectConnection OPEN transport=<pika.adapters.utils.io_services_utils._AsyncPlaintextTransport object at 0x00000258EEEA1B70> params=<ConnectionParameters host=localhost port=5672 virtual_host=testhost ssl=False>>
AMQPConnectionWorkflow - reporting success: <SelectConnection OPEN transport=<pika.adapters.utils.io_services_utils._AsyncPlaintextTransport object at 0x00000258EEEA1B70> params=<ConnectionParameters host=localhost port=5672 virtual_host=testhost ssl=False>>
Connection workflow succeeded: <SelectConnection OPEN transport=<pika.adapters.utils.io_services_utils._AsyncPlaintextTransport object at 0x00000258EEEA1B70> params=<ConnectionParameters host=localhost port=5672 virtual_host=testhost ssl=False>>
Created channel=1
Exception occurred while handling uri: 'http://127.0.0.1:8075/python/bpDsDynamicInfo'
Traceback (most recent call last):
  File "D:\Program Files\Anaconda2\envs\python35\lib\site-packages\sanic\app.py", line 915, in handle_request
    response = handler(request, *args, **kwargs)
  File "G:\Project\Trainer\trainer\backend\app\datasetinfo\dynamic\view.py", line 30, in request_dataset_dynamic_info
    dsDynamicInfoDict = interface_dataset_dynamic_info(trainName,isGetAll)
  File "G:\Project\Trainer\trainer\backend\app\datasetinfo\dynamic\model.py", line 18, in interface_dataset_dynamic_info
    dsDynamicInfoDict = mq_to_sql(topic,tablename,trainName,isGetAll,isOnlyOne)
  File "G:\Project\Trainer\trainer\backend\app\basemodel.py", line 58, in mq_to_sql
    tdsStaticInfoTable = pd.read_sql(querySql,con=engine)
UnboundLocalError: local variable 'engine' referenced before assignment

Goin' Fast @ http://127.0.0.1:8075
Sanic tried to use loop.add_signal_handler but it is not implemented on this platform.
Sanic tried to use loop.add_signal_handler but it is not implemented on this platform.
Starting worker [41692]
Pika version 1.1.0 connecting to ('::1', 5672, 0, 0)
Socket connected: <socket.socket fd=1524, family=AddressFamily.AF_INET6, type=SocketKind.SOCK_STREAM, proto=6, laddr=('::1', 59228, 0, 0), raddr=('::1', 5672, 0, 0)>
Streaming transport linked up: (<pika.adapters.utils.io_services_utils._AsyncPlaintextTransport object at 0x0000029954622B70>, _StreamingProtocolShim: <SelectConnection PROTOCOL transport=<pika.adapters.utils.io_services_utils._AsyncPlaintextTransport object at 0x0000029954622B70> params=<ConnectionParameters host=localhost port=5672 virtual_host=testhost ssl=False>>).
AMQPConnector - reporting success: <SelectConnection OPEN transport=<pika.adapters.utils.io_services_utils._AsyncPlaintextTransport object at 0x0000029954622B70> params=<ConnectionParameters host=localhost port=5672 virtual_host=testhost ssl=False>>
AMQPConnectionWorkflow - reporting success: <SelectConnection OPEN transport=<pika.adapters.utils.io_services_utils._AsyncPlaintextTransport object at 0x0000029954622B70> params=<ConnectionParameters host=localhost port=5672 virtual_host=testhost ssl=False>>
Connection workflow succeeded: <SelectConnection OPEN transport=<pika.adapters.utils.io_services_utils._AsyncPlaintextTransport object at 0x0000029954622B70> params=<ConnectionParameters host=localhost port=5672 virtual_host=testhost ssl=False>>
Created channel=1

